
  0%|                                     | 10/200000 [00:01<7:50:12,  7.09it/s]
Begin
TRAIN views are [ 0  1  2  3  4  5  6  7  8  9 10 11 12 13 14 15 16 17 18 19 20 21 22 23
 24 25 26 27 28 29 30 31 32 33 34 35 36 37 38 39 40 41 42 43 44 45 46 47
 48 49 50 51 52 53 54 55 56 57 58 59 60 61 62 63 64 65 66 67 68 69 70 71
 72 73 74 75 76 77 78 79 80 81 82 83 84 85 86 87 88 89 90 91 92 93 94 95
 96 97 98 99]
TEST views are [113 114 115 116 117 118 119 120 121 122 123 124 125 126 127 128 129 130
 131 132 133 134 135 136 137]






  0%|                                     | 95/200000 [00:13<7:55:35,  7.01it/s]

  0%|                                    | 99/200000 [00:23<13:13:55,  4.20it/s]
Traceback (most recent call last):
  File "/home2/shaurya.dewan/.local/lib/python3.9/site-packages/PIL/Image.py", line 2828, in fromarray
    mode, rawmode = _fromarray_typemap[typekey]
KeyError: ((1, 1, 400), '|u1')
The above exception was the direct cause of the following exception:
Traceback (most recent call last):
  File "/home2/shaurya.dewan/NOCs/nerf-pytorch/run_nerf.py", line 966, in <module>
    train()
  File "/home2/shaurya.dewan/NOCs/nerf-pytorch/run_nerf.py", line 912, in train
    "Image": [wandb.Image(rgb)],
  File "/home2/shaurya.dewan/miniconda3/envs/nerf/lib/python3.9/site-packages/wandb/sdk/data_types/image.py", line 145, in __init__
    self._initialize_from_data(data_or_path, mode)
  File "/home2/shaurya.dewan/miniconda3/envs/nerf/lib/python3.9/site-packages/wandb/sdk/data_types/image.py", line 265, in _initialize_from_data
    self._image = pil_image.fromarray(
  File "/home2/shaurya.dewan/.local/lib/python3.9/site-packages/PIL/Image.py", line 2830, in fromarray
    raise TypeError("Cannot handle this data type: %s, %s" % typekey) from e
TypeError: Cannot handle this data type: (1, 1, 400), |u1